Workbook

Sheet Read me
A1: EPG BvA - 2026-09 (DRAFT, BOOKS NOT CLOSED)
A2: Entity: Eden Partner Group (EPG). Prepared 2026-10-16, acting for Joel Fairchild ahead of hand-off. Read-only: nothing was written to QuickBooks, Gusto or the bank.
A4: STATUS FLAGS
A5: 1. Books not closed. Joel owns Day 3 close; none of the QuickBooks figures here are confirmed.
A6: 2. Basis unproven. The QuickBooks connector gives no accrual/cash flag on the P&L. Sales by Customer returned identical totals on accrual and cash ($59,100, one customer, June only).
A7: 3. QuickBooks has almost no 2026 invoices: 0 invoices in the last 180 days, 0 open A/R at 10/15, and only $59,100 of customer-tied sales YTD. The Hub shows $982,428 billed YTD. September P&L income ($117,500) is not tied to a customer.
A8: 4. Budget is blank: no monthly revenue budget is approved. Annual target $2,350,000 is on the Hub; the proposed monthly ramp is on the BvA tab and is marked PROPOSED.
A9: 5. Payments received are NOT filled in. Bank and deposit data are not available to this connector; the Hub "Date: $ In" column is empty. Column "Paid (date / amount)" on the Invoice Ledger needs the bank statement or QuickBooks deposits.
A10: 6. Invoice "date sent" comes from the last outbox activity on kev@edenexec.com for that invoice number, not the exact send time. Jan to Feb invoices were not found in the outbox by subject.
A12: TABS
A13: Invoice Ledger: one row per Hub invoice (client, role, amount, terms, due date, outbox evidence, payment match).
A14: Client names tidied (Megwatt to Megawatt; PENTA and PENTA So. Cal merged; Pence variants merged; Baker and Baker Construction merged; Baker Concrete kept separate: confirm).
... A20: PRIVACY: totals by client and role only. No candidate names, salaries or bank details.

Sheet Invoice Ledger
A1: Invoice # | B1: Client | C1: Role | D1: Start date | E1: Net terms (days) | F1: Due date | G1: Fee | H1: Discount | I1: Billed (fee less discount) | J1: Month of start | K1: Outbox last activity | L1: Paid (date / amount) | M1: Status | N1: Notes
A2: 62021 | B2: PB South | C2: Sr. Superintendent | D2: 46027 | E2: 30 | F2: =IF(D2="","",D2+E2) | G2: 30600 | H2: 7500 | I2: =G2-H2 | J2: =IF(D2="","",TEXT(D2,"yyyy-mm")) | M2: =IF(I2=0,"No fee",IF(D2="","Check start date",IF(D2>DATE(2026,10,16),"Future start, not yet earned",IF(L2<>"","Paid?",IF(K2="","Not found in outbox",IF(F2<DATE(2026,10,16),"Past due or paid: check bank","Sent, not yet due")))))) | N2: Terms blank: Net 30 assumed.
A3: 62022 | B3: Swinerton - DFW | C3: Superintendent | D3: 46048 | E3: 30 | F3: =IF(D3="","",D3+E3) | G3: 30000 | H3: 0 | I3: =G3-H3 | J3: =IF(D3="","",TEXT(D3,"yyyy-mm")) | M3: =IF(I3=0,"No fee",IF(D3="","Check start date",IF(D3>DATE(2026,10,16),"Future start, not yet earned",IF(L3<>"","Paid?",IF(K3="","Not found in outbox",IF(F3<DATE(2026,10,16),"Past due or paid: check bank","Sent, not yet due")))))) | N3: Terms blank: Net 30 assumed.
A4: 62023 | B4: PB South | C4: N/A | D4: 46037 | E4: 30 | F4: =IF(D4="","",D4+E4) | G4: 7500 | H4: 0 | I4: =G4-H4 | J4: =IF(D4="","",TEXT(D4,"yyyy-mm")) | M4: =IF(I4=0,"No fee",IF(D4="","Check start date",IF(D4>DATE(2026,10,16),"Future start, not yet earned",IF(L4<>"","Paid?",IF(K4="","Not found in outbox",IF(F4<DATE(2026,10,16),"Past due or paid: check bank","Sent, not yet due")))))) | N4: Terms blank: Net 30 assumed.
A5: 62024 | B5: PENTA | C5: Sr. Superintendent | D5: 46038 | E5: 30 | F5: =IF(D5="","",D5+E5) | G5: 14250 | H5: 0 | I5: =G5-H5 | J5: =IF(D5="","",TEXT(D5,"yyyy-mm")) | M5: =IF(I5=0,"No fee",IF(D5="","Check start date",IF(D5>DATE(2026,10,16),"Future start, not yet earned",IF(L5<>"","Paid?",IF(K5="","Not found in outbox",IF(F5<DATE(2026,10,16),"Past due or paid: check bank","Sent, not yet due")))))) | N5: Terms blank: Net 30 assumed.
A6: 62025 | B6: PB South | C6: Project Acct. / Office Mngr | D6: 46057 | E6: 30 | F6: =IF(D6="","",D6+E6) | G6: 19800 | H6: 7500 | I6: =G6-H6 | J6: =IF(D6="","",TEXT(D6,"yyyy-mm")) | M6: =IF(I6=0,"No fee",IF(D6="","Check start date",IF(D6>DATE(2026,10,16),"Future start, not yet earned",IF(L6<>"","Paid?",IF(K6="","Not found in outbox",IF(F6<DATE(2026,10,16),"Past due or paid: check bank","Sent, not yet due")))))) | N6: Terms blank: Net 30 assumed.
A7: 62026-A | B7: Beck Group | C7: Drywall Sr. PM | D7: 46062 | E7: 30 | F7: =IF(D7="","",D7+E7) | G7: 15000 | H7: 0 | I7: =G7-H7 | J7: =IF(D7="","",TEXT(D7,"yyyy-mm")) | M7: =IF(I7=0,"No fee",IF(D7="","Check start date",IF(D7>DATE(2026,10,16),"Future start, not yet earned",IF(L7<>"","Paid?",IF(K7="","Not found in outbox",IF(F7<DATE(2026,10,16),"Past due or paid: check bank","Sent, not yet due")))))) | N7: Split bill with 62026-B (net 30 and net 90).
A8: 62026-B | B8: Beck Group | C8: Drywall Sr. PM | D8: 46062 | E8: 90 | F8: =IF(D8="","",D8+E8) | G8: 15000 | H8: 0 | I8: =G8-H8 | J8: =IF(D8="","",TEXT(D8,"yyyy-mm")) | M8: =IF(I8=0,"No fee",IF(D8="","Check start date",IF(D8>DATE(2026,10,16),"Future start, not yet earned",IF(L8<>"","Paid?",IF(K8="","Not found in outbox",IF(F8<DATE(2026,10,16),"Past due or paid: check bank","Sent, not yet due")))))) | N8: Second $15,000 line for the same Beck Group start (net 90). Confirm it is a split bill, not a double count.
A9: 62027 | B9: PB South | C9: MEP Sr. PM | D9: 46069 | E9: 30 | F9: =IF(D9="","",D9+E9) | G9: 36000 | H9: 0 | I9: =G9-H9 | J9: =IF(D9="","",TEXT(D9,"yyyy-mm")) | M9: =IF(I9=0,"No fee",IF(D9="","Check start date",IF(D9>DATE(2026,10,16),"Future start, not yet earned",IF(L9<>"","Paid?",IF(K9="","Not found in outbox",IF(F9<DATE(2026,10,16),"Past due or paid: check bank","Sent, not yet due")))))) | N9: Terms blank: Net 30 assumed.
A10: 62028 | B10: PB South | C10: Assistnat Project Manager | D10: 46076 | E10: 30 | F10: =IF(D10="","",D10+E10) | G10: 0 | H10: 0 | I10: =G10-H10 | J10: =IF(D10="","",TEXT(D10,"yyyy-mm")) | M10: =IF(I10=0,"No fee",IF(D10="","Check start date",IF(D10>DATE(2026,10,16),"Future start, not yet earned",IF(L10<>"","Paid?",IF(K10="","Not found in outbox",IF(F10<DATE(2026,10,16),"Past due or paid: check bank","Sent, not yet due")))))) | N10: $0 fee. Terms blank: Net 30 assumed.
A11: 62029 | B11: PB South | C11: N/A | D11: 46068 | E11: 30 | F11: =IF(D11="","",D11+E11) | G11: 7500 | H11: 0 | I11: =G11-H11 | J11: =IF(D11="","",TEXT(D11,"yyyy-mm")) | M11: =IF(I11=0,"No fee",IF(D11="","Check start date",IF(D11>DATE(2026,10,16),"Future start, not yet earned",IF(L11<>"","Paid?",IF(K11="","Not found in outbox",IF(F11<DATE(2026,10,16),"Past due or paid: check bank","Sent, not yet due")))))) | N11: Start date typed 2/15/0206 in the Hub; treated as 2/15/2026. Terms blank: Net 30 assumed.
A12: 62030 | B12: Jackson Contracting | C12: N/A | E12: 30 | F12: =IF(D12="","",D12+E12) | G12: 8333 | H12: 0 | I12: =G12-H12 | J12: =IF(D12="","",TEXT(D12,"yyyy-mm")) | M12: =IF(I12=0,"No fee",IF(D12="","Check start date",IF(D12>DATE(2026,10,16),"Future start, not yet earned",IF(L12<>"","Paid?",IF(K12="","Not found in outbox",IF(F12<DATE(2026,10,16),"Past due or paid: check bank","Sent, not yet due")))))) | N12: No start date in the Hub. Terms blank: Net 30 assumed.
A13: 62031 | B13: Baker Concrete | C13: Project Executive | D13: 46080 | E13: 30 | F13: =IF(D13="","",D13+E13) | G13: 56320 | H13: 0 | I13: =G13-H13 | J13: =IF(D13="","",TEXT(D13,"yyyy-mm")) | M13: =IF(I13=0,"No fee",IF(D13="","Check start date",IF(D13>DATE(2026,10,16),"Future start, not yet earned",IF(L13<>"","Paid?",IF(K13="","Not found in outbox",IF(F13<DATE(2026,10,16),"Past due or paid: check bank","Sent, not yet due")))))) | N13: Terms blank: Net 30 assumed.
A14: 62032 | B14: PB South | C14: Sr. Project Manager | D14: 46096 | E14: 30 | F14: =IF(D14="","",D14+E14) | G14: 40500 | H14: 7500 | I14: =G14-H14 | J14: =IF(D14="","",TEXT(D14,"yyyy-mm")) | M14: =IF(I14=0,"No fee",IF(D14="","Check start date",IF(D14>DATE(2026,10,16),"Future start, not yet earned",IF(L14<>"","Paid?",IF(K14="","Not found in outbox",IF(F14<DATE(2026,10,16),"Past due or paid: check bank","Sent, not yet due")))))) | N14: Terms blank: Net 30 assumed.
A15: 62033 | B15: PB South | C15: NA | E15: 30 | F15: =IF(D15="","",D15+E15) | G15: 7500 | H15: 0 | I15: =G15-H15 | J15: =IF(D15="","",TEXT(D15,"yyyy-mm")) | M15: =IF(I15=0,"No fee",IF(D15="","Check start date",IF(D15>DATE(2026,10,16),"Future start, not yet earned",IF(L15<>"","Paid?",IF(K15="","Not found in outbox",IF(F15<DATE(2026,10,16),"Past due or paid: check bank","Sent, not yet due")))))) | N15: No start date; "due by 15th". Terms blank: Net 30 assumed.
A16: 62034 | B16: Megawatt | D16: 46111 | E16: 30 | F16: =IF(D16="","",D16+E16) | G16: 0 | H16: 0 | I16: =G16-H16 | J16: =IF(D16="","",TEXT(D16,"yyyy-mm")) | M16: =IF(I16=0,"No fee",IF(D16="","Check start date",IF(D16>DATE(2026,10,16),"Future start, not yet earned",IF(L16<>"","Paid?",IF(K16="","Not found in outbox",IF(F16<DATE(2026,10,16),"Past due or paid: check bank","Sent, not yet due")))))) | N16: $0 fee. Terms blank: Net 30 assumed.
A17: 62035 | B17: Megawatt | C17: Scheduler | D17: 46104 | E17: 40 | F17: =IF(D17="","",D17+E17) | G17: 31000 | H17: 0 | I17: =G17-H17 | J17: =IF(D17="","",TEXT(D17,"yyyy-mm")) | M17: =IF(I17=0,"No fee",IF(D17="","Check start date",IF(D17>DATE(2026,10,16),"Future start, not yet earned",IF(L17<>"","Paid?",IF(K17="","Not found in outbox",IF(F17<DATE(2026,10,16),"Past due or paid: check bank","Sent, not yet due"))))))
A18: 62036 | B18: Moss Construction | C18: Safety Manager | D18: 46111 | E18: 30 | F18: =IF(D18="","",D18+E18) | G18: 16000 | H18: 0 | I18: =G18-H18 | J18: =IF(D18="","",TEXT(D18,"yyyy-mm")) | K18: 46111 | M18: =IF(I18=0,"No fee",IF(D18="","Check start date",IF(D18>DATE(2026,10,16),"Future start, not yet earned",IF(L18<>"","Paid?",IF(K18="","Not found in outbox",IF(F18<DATE(2026,10,16),"Past due or paid: check bank","Sent, not yet due"))))))
A19: 62037 | B19: Megawatt | C19: Superintendent | D19: 46118 | E19: 40 | F19: =IF(D19="","",D19+E19) | G19: 36000 | H19: 0 | I19: =G19-H19 | J19: =IF(D19="","",TEXT(D19,"yyyy-mm")) | K19: 46118 | M19: =IF(I19=0,"No fee",IF(D19="","Check start date",IF(D19>DATE(2026,10,16),"Future start, not yet earned",IF(L19<>"","Paid?",IF(K19="","Not found in outbox",IF(F19<DATE(2026,10,16),"Past due or paid: check bank","Sent, not yet due"))))))
A20: 62038 | B20: PENTA | C20: Scheduler | D20: 46098 | E20: 0 | F20: =IF(D20="","",D20+E20) | G20: 8600 | H20: 0 | I20: =G20-H20 | J20: =IF(D20="","",TEXT(D20,"yyyy-mm")) | K20: 46100 | M20: =IF(I20=0,"No fee",IF(D20="","Check start date",IF(D20>DATE(2026,10,16),"Future start, not yet earned",IF(L20<>"","Paid?",IF(K20="","Not found in outbox",IF(F20<DATE(2026,10,16),"Past due or paid: check bank","Sent, not yet due"))))))
A21: 62039 | B21: Pence | C21: N/A | D21: 46113 | E21: 30 | F21: =IF(D21="","",D21+E21) | G21: 7500 | H21: 0 | I21: =G21-H21 | J21: =IF(D21="","",TEXT(D21,"yyyy-mm")) | K21: 46113 | M21: =IF(I21=0,"No fee",IF(D21="","Check start date",IF(D21>DATE(2026,10,16),"Future start, not yet earned",IF(L21<>"","Paid?",IF(K21="","Not found in outbox",IF(F21<DATE(2026,10,16),"Past due or paid: check bank","Sent, not yet due")))))) | N21: Terms blank: Net 30 assumed.
A22: 62040 | B22: Pence | C22: N/A | D22: 46143 | E22: 30 | F22: =IF(D22="","",D22+E22) | G22: 7500 | H22: 0 | I22: =G22-H22 | J22: =IF(D22="","",TEXT(D22,"yyyy-mm")) | K22: 46147 | M22: =IF(I22=0,"No fee",IF(D22="","Check start date",IF(D22>DATE(2026,10,16),"Future start, not yet earned",IF(L22<>"","Paid?",IF(K22="","Not found in outbox",IF(F22<DATE(2026,10,16),"Past due or paid: check bank","Sent, not yet due")))))) | N22: Terms blank: Net 30 assumed.
A23: 62041 | B23: Megawatt | C23: Project Manager | D23: 46132 | E23: 40 | F23: =IF(D23="","",D23+E23) | G23: 39000 | H23: 0 | I23: =G23-H23 | J23: =IF(D23="","",TEXT(D23,"yyyy-mm")) | K23: 46132 | M23: =IF(I23=0,"No fee",IF(D23="","Check start date",IF(D23>DATE(2026,10,16),"Future start, not yet earned",IF(L23<>"","Paid?",IF(K23="","Not found in outbox",IF(F23<DATE(2026,10,16),"Past due or paid: check bank","Sent, not yet due"))))))
A24: 62042 | B24: Hoffman | C24: Supers - Tx/Boise | D24: 46160 | E24: 30 | F24: =IF(D24="","",D24+E24) | G24: 40000 | H24: 0 | I24: =G24-H24 | J24: =IF(D24="","",TEXT(D24,"yyyy-mm")) | K24: 46170 | M24: =IF(I24=0,"No fee",IF(D24="","Check start date",IF(D24>DATE(2026,10,16),"Future start, not yet earned",IF(L24<>"","Paid?",IF(K24="","Not found in outbox",IF(F24<DATE(2026,10,16),"Past due or paid: check bank","Sent, not yet due")))))) | N24: Terms blank: Net 30 assumed.
A25: 62043 | B25: PENTA | C25: Regional Scheduling Manager | D25: 46181 | E25: 30 | F25: =IF(D25="","",D25+E25) | G25: 39000 | H25: 8600 | I25: =G25-H25 | J25: =IF(D25="","",TEXT(D25,"yyyy-mm")) | K25: 46181 | M25: =IF(I25=0,"No fee",IF(D25="","Check start date",IF(D25>DATE(2026,10,16),"Future start, not yet earned",IF(L25<>"","Paid?",IF(K25="","Not found in outbox",IF(F25<DATE(2026,10,16),"Past due or paid: check bank","Sent, not yet due"))))))
A26: 62044 | B26: Pence | C26: N/A | D26: 46174 | E26: 30 | F26: =IF(D26="","",D26+E26) | G26: 0 | H26: 0 | I26: =G26-H26 | J26: =IF(D26="","",TEXT(D26,"yyyy-mm")) | M26: =IF(I26=0,"No fee",IF(D26="","Check start date",IF(D26>DATE(2026,10,16),"Future start, not yet earned",IF(L26<>"","Paid?",IF(K26="","Not found in outbox",IF(F26<DATE(2026,10,16),"Past due or paid: check bank","Sent, not yet due")))))) | N26: $0 fee. Terms blank: Net 30 assumed.
A27: 62045 | B27: PB South | C27: N/A | E27: 30 | F27: =IF(D27="","",D27+E27) | G27: 7500 | H27: 0 | I27: =G27-H27 | J27: =IF(D27="","",TEXT(D27,"yyyy-mm")) | M27: =IF(I27=0,"No fee",IF(D27="","Check start date",IF(D27>DATE(2026,10,16),"Future start, not yet earned",IF(L27<>"","Paid?",IF(K27="","Not found in outbox",IF(F27<DATE(2026,10,16),"Past due or paid: check bank","Sent, not yet due")))))) | N27: Terms blank: Net 30 assumed.
A28: 62046 | B28: Baker Construction | C28: Senior Superintendent | D28: 46216 | E28: 30 | F28: =IF(D28="","",D28+E28) | G28: 55000 | H28: 0 | I28: =G28-H28 | J28: =IF(D28="","",TEXT(D28,"yyyy-mm")) | K28: 46216 | M28: =IF(I28=0,"No fee",IF(D28="","Check start date",IF(D28>DATE(2026,10,16),"Future start, not yet earned",IF(L28<>"","Paid?",IF(K28="","Not found in outbox",IF(F28<DATE(2026,10,16),"Past due or paid: check bank","Sent, not yet due")))))) | N28: Re-sent 9/25 ("Net 30 from 8/10"): confirm payment status.
A29: 62047 | B29: Carmel Partners | C29: Assistant Project Manager | D29: 46216 | E29: 30 | F29: =IF(D29="","",D29+E29) | G29: 31500 | H29: 0 | I29: =G29-H29 | J29: =IF(D29="","",TEXT(D29,"yyyy-mm")) | K29: 46189 | M29: =IF(I29=0,"No fee",IF(D29="","Check start date",IF(D29>DATE(2026,10,16),"Future start, not yet earned",IF(L29<>"","Paid?",IF(K29="","Not found in outbox",IF(F29<DATE(2026,10,16),"Past due or paid: check bank","Sent, not yet due"))))))
A30: 62048 | B30: Carmel Partners | C30: Assistant Superintendent | D30: 46209 | E30: 30 | F30: =IF(D30="","",D30+E30) | G30: 30375 | H30: 0 | I30: =G30-H30 | J30: =IF(D30="","",TEXT(D30,"yyyy-mm")) | K30: 46209 | M30: =IF(I30=0,"No fee",IF(D30="","Check start date",IF(D30>DATE(2026,10,16),"Future start, not yet earned",IF(L30<>"","Paid?",IF(K30="","Not found in outbox",IF(F30<DATE(2026,10,16),"Past due or paid: check bank","Sent, not yet due"))))))
A31: 62049 | B31: Kaweah Health | C31: ? | D31: 46244 | E31: 30 | F31: =IF(D31="","",D31+E31) | G31: 11500 | H31: 0 | I31: =G31-H31 | J31: =IF(D31="","",TEXT(D31,"yyyy-mm")) | K31: 46237 | M31: =IF(I31=0,"No fee",IF(D31="","Check start date",IF(D31>DATE(2026,10,16),"Future start, not yet earned",IF(L31<>"","Paid?",IF(K31="","Not found in outbox",IF(F31<DATE(2026,10,16),"Past due or paid: check bank","Sent, not yet due"))))))
A32: 62050 | B32: Megawatt | C32: Senior Project Manager | E32: 30 | F32: =IF(D32="","",D32+E32) | G32: 0 | H32: 0 | I32: =G32-H32 | J32: =IF(D32="","",TEXT(D32,"yyyy-mm")) | M32: =IF(I32=0,"No fee",IF(D32="","Check start date",IF(D32>DATE(2026,10,16),"Future start, not yet earned",IF(L32<>"","Paid?",IF(K32="","Not found in outbox",IF(F32<DATE(2026,10,16),"Past due or paid: check bank","Sent, not yet due")))))) | N32: Start TBD, $0.
A33: 62051 | B33: Hoffman | C33: Superintrendent | D33: 46230 | E33: 30 | F33: =IF(D33="","",D33+E33) | G33: 0 | H33: 0 | I33: =G33-H33 | J33: =IF(D33="","",TEXT(D33,"yyyy-mm")) | M33: =IF(I33=0,"No fee",IF(D33="","Check start date",IF(D33>DATE(2026,10,16),"Future start, not yet earned",IF(L33<>"","Paid?",IF(K33="","Not found in outbox",IF(F33<DATE(2026,10,16),"Past due or paid: check bank","Sent, not yet due")))))) | N33: $0 fee. Terms blank: Net 30 assumed.
A34: 62502 | B34: Megawatt | C34: MEP Superintendent | D34: 46258 | E34: 40 | F34: =IF(D34="","",D34+E34) | G34: 40000 | H34: 0 | I34: =G34-H34 | J34: =IF(D34="","",TEXT(D34,"yyyy-mm")) | K34: 46273 | M34: =IF(I34=0,"No fee",IF(D34="","Check start date",IF(D34>DATE(2026,10,16),"Future start, not yet earned",IF(L34<>"","Paid?",IF(K34="","Not found in outbox",IF(F34<DATE(2026,10,16),"Past due or paid: check bank","Sent, not yet due")))))) | N34: Doc # 62502 in outbox; Hub shows 62502 and 62053 both $40,000 MEP Superintendent, same start. Possible duplicate or two hires: ask Radar.
A35: 62053 | B35: Megawatt | C35: MEP Superintendent | D35: 46258 | E35: 40 | F35: =IF(D35="","",D35+E35) | G35: 40000 | H35: 0 | I35: =G35-H35 | J35: =IF(D35="","",TEXT(D35,"yyyy-mm")) | M35: =IF(I35=0,"No fee",IF(D35="","Check start date",IF(D35>DATE(2026,10,16),"Future start, not yet earned",IF(L35<>"","Paid?",IF(K35="","Not found in outbox",IF(F35<DATE(2026,10,16),"Past due or paid: check bank","Sent, not yet due")))))) | N35: Same client, role, amount and start as 62502: confirm two separate placements.
A36: 62054 | B36: Megawatt | C36: General Superintendent | E36: 40 | F36: =IF(D36="","",D36+E36) | G36: 45000 | H36: 0 | I36: =G36-H36 | J36: =IF(D36="","",TEXT(D36,"yyyy-mm")) | M36: =IF(I36=0,"No fee",IF(D36="","Check start date",IF(D36>DATE(2026,10,16),"Future start, not yet earned",IF(L36<>"","Paid?",IF(K36="","Not found in outbox",IF(F36<DATE(2026,10,16),"Past due or paid: check bank","Sent, not yet due")))))) | N36: Start is a note ("October"), not a date. $45,000 not yet invoiced.
A37: 62055 | B37: PB South | C37: General Superintendent | D37: 46279 | E37: 90 | F37: =IF(D37="","",D37+E37) | G37: 0 | H37: 0 | I37: =G37-H37 | J37: =IF(D37="","",TEXT(D37,"yyyy-mm")) | M37: =IF(I37=0,"No fee",IF(D37="","Check start date",IF(D37>DATE(2026,10,16),"Future start, not yet earned",IF(L37<>"","Paid?",IF(K37="","Not found in outbox",IF(F37<DATE(2026,10,16),"Past due or paid: check bank","Sent, not yet due")))))) | N37: No fee entered. Terms "90?" unconfirmed.
A38: 62056 | B38: PB South | C38: Superintendent | D38: 46267 | E38: 90 | F38: =IF(D38="","",D38+E38) | G38: 29700 | H38: 0 | I38: =G38-H38 | J38: =IF(D38="","",TEXT(D38,"yyyy-mm")) | K38: 46304 | M38: =IF(I38=0,"No fee",IF(D38="","Check start date",IF(D38>DATE(2026,10,16),"Future start, not yet earned",IF(L38<>"","Paid?",IF(K38="","Not found in outbox",IF(F38<DATE(2026,10,16),"Past due or paid: check bank","Sent, not yet due")))))) | N38: Terms "90?" unconfirmed.
A39: 62057 | B39: PB South | C39: Assistant Superintendent | D39: 46289 | E39: 90 | F39: =IF(D39="","",D39+E39) | G39: 6750 | H39: 0 | I39: =G39-H39 | J39: =IF(D39="","",TEXT(D39,"yyyy-mm")) | K39: 46302 | M39: =IF(I39=0,"No fee",IF(D39="","Check start date",IF(D39>DATE(2026,10,16),"Future start, not yet earned",IF(L39<>"","Paid?",IF(K39="","Not found in outbox",IF(F39<DATE(2026,10,16),"Past due or paid: check bank","Sent, not yet due")))))) | N39: Terms "90?" unconfirmed.
A40: 62058 | B40: PB South | C40: Project Manager | E40: 90 | F40: =IF(D40="","",D40+E40) | G40: 0 | H40: 0 | I40: =G40-H40 | J40: =IF(D40="","",TEXT(D40,"yyyy-mm")) | M40: =IF(I40=0,"No fee",IF(D40="","Check start date",IF(D40>DATE(2026,10,16),"Future start, not yet earned",IF(L40<>"","Paid?",IF(K40="","Not found in outbox",IF(F40<DATE(2026,10,16),"Past due or paid: check bank","Sent, not yet due")))))) | N40: Start "December", no fee entered. Terms "90?" unconfirmed.
...

Sheet Revenue YTD
A1: Month of start | B1: Billed (Hub) | C1: Invoices | D1: Cumulative
A2: 2026-01 | B2: =SUMIFS('Invoice Ledger'!I:I,'Invoice Ledger'!J:J,A2) | C2: =COUNTIFS('Invoice Ledger'!J:J,A2,'Invoice Ledger'!I:I,">0") | D2: =SUM($B$2:B2)
A3: 2026-02 | B3: =SUMIFS('Invoice Ledger'!I:I,'Invoice Ledger'!J:J,A3) | C3: =COUNTIFS('Invoice Ledger'!J:J,A3,'Invoice Ledger'!I:I,">0") | D3: =SUM($B$2:B3)
A4: 2026-03 | B4: =SUMIFS('Invoice Ledger'!I:I,'Invoice Ledger'!J:J,A4) | C4: =COUNTIFS('Invoice Ledger'!J:J,A4,'Invoice Ledger'!I:I,">0") | D4: =SUM($B$2:B4)
A5: 2026-04 | B5: =SUMIFS('Invoice Ledger'!I:I,'Invoice Ledger'!J:J,A5) | C5: =COUNTIFS('Invoice Ledger'!J:J,A5,'Invoice Ledger'!I:I,">0") | D5: =SUM($B$2:B5)
A6: 2026-05 | B6: =SUMIFS('Invoice Ledger'!I:I,'Invoice Ledger'!J:J,A6) | C6: =COUNTIFS('Invoice Ledger'!J:J,A6,'Invoice Ledger'!I:I,">0") | D6: =SUM($B$2:B6)
A7: 2026-06 | B7: =SUMIFS('Invoice Ledger'!I:I,'Invoice Ledger'!J:J,A7) | C7: =COUNTIFS('Invoice Ledger'!J:J,A7,'Invoice Ledger'!I:I,">0") | D7: =SUM($B$2:B7)
A8: 2026-07 | B8: =SUMIFS('Invoice Ledger'!I:I,'Invoice Ledger'!J:J,A8) | C8: =COUNTIFS('Invoice Ledger'!J:J,A8,'Invoice Ledger'!I:I,">0") | D8: =SUM($B$2:B8)
A9: 2026-08 | B9: =SUMIFS('Invoice Ledger'!I:I,'Invoice Ledger'!J:J,A9) | C9: =COUNTIFS('Invoice Ledger'!J:J,A9,'Invoice Ledger'!I:I,">0") | D9: =SUM($B$2:B9)
A10: 2026-09 | B10: =SUMIFS('Invoice Ledger'!I:I,'Invoice Ledger'!J:J,A10) | C10: =COUNTIFS('Invoice Ledger'!J:J,A10,'Invoice Ledger'!I:I,">0") | D10: =SUM($B$2:B10)
A11: 2026-10 | B11: =SUMIFS('Invoice Ledger'!I:I,'Invoice Ledger'!J:J,A11) | C11: =COUNTIFS('Invoice Ledger'!J:J,A11,'Invoice Ledger'!I:I,">0") | D11: =SUM($B$2:B11)
A12: 2026-11 | B12: =SUMIFS('Invoice Ledger'!I:I,'Invoice Ledger'!J:J,A12) | C12: =COUNTIFS('Invoice Ledger'!J:J,A12,'Invoice Ledger'!I:I,">0") | D12: =SUM($B$2:B12)
A13: 2026-12 | B13: =SUMIFS('Invoice Ledger'!I:I,'Invoice Ledger'!J:J,A13) | C13: =COUNTIFS('Invoice Ledger'!J:J,A13,'Invoice Ledger'!I:I,">0") | D13: =SUM($B$2:B13)
A14: No start date | B14: ='Invoice Ledger'!I49-SUM(B2:B13)
A15: Total | B15: =SUM(B2:B14)
A16: Earned to date (start on or before 10/16) | B16: =SUMIFS('Invoice Ledger'!I:I,'Invoice Ledger'!D:D,"<="&DATE(2026,10,16))
A17: Future starts | B17: =SUMIFS('Invoice Ledger'!I:I,'Invoice Ledger'!D:D,">"&DATE(2026,10,16))
A19: Client | B19: Billed (Hub) | C19: Invoices
A20: Baker Concrete | B20: =SUMIFS('Invoice Ledger'!I:I,'Invoice Ledger'!B:B,A20) | C20: =COUNTIFS('Invoice Ledger'!B:B,A20,'Invoice Ledger'!I:I,">0")
A21: Baker Construction | B21: =SUMIFS('Invoice Ledger'!I:I,'Invoice Ledger'!B:B,A21) | C21: =COUNTIFS('Invoice Ledger'!B:B,A21,'Invoice Ledger'!I:I,">0")
A22: Beck Group | B22: =SUMIFS('Invoice Ledger'!I:I,'Invoice Ledger'!B:B,A22) | C22: =COUNTIFS('Invoice Ledger'!B:B,A22,'Invoice Ledger'!I:I,">0")
A23: Carmel Partners | B23: =SUMIFS('Invoice Ledger'!I:I,'Invoice Ledger'!B:B,A23) | C23: =COUNTIFS('Invoice Ledger'!B:B,A23,'Invoice Ledger'!I:I,">0")
A24: Hoffman | B24: =SUMIFS('Invoice Ledger'!I:I,'Invoice Ledger'!B:B,A24) | C24: =COUNTIFS('Invoice Ledger'!B:B,A24,'Invoice Ledger'!I:I,">0")
A25: Jackson Contracting | B25: =SUMIFS('Invoice Ledger'!I:I,'Invoice Ledger'!B:B,A25) | C25: =COUNTIFS('Invoice Ledger'!B:B,A25,'Invoice Ledger'!I:I,">0")
A26: Kaweah Health | B26: =SUMIFS('Invoice Ledger'!I:I,'Invoice Ledger'!B:B,A26) | C26: =COUNTIFS('Invoice Ledger'!B:B,A26,'Invoice Ledger'!I:I,">0")
A27: Megawatt | B27: =SUMIFS('Invoice Ledger'!I:I,'Invoice Ledger'!B:B,A27) | C27: =COUNTIFS('Invoice Ledger'!B:B,A27,'Invoice Ledger'!I:I,">0")
A28: Moss Construction | B28: =SUMIFS('Invoice Ledger'!I:I,'Invoice Ledger'!B:B,A28) | C28: =COUNTIFS('Invoice Ledger'!B:B,A28,'Invoice Ledger'!I:I,">0")
A29: PB South | B29: =SUMIFS('Invoice Ledger'!I:I,'Invoice Ledger'!B:B,A29) | C29: =COUNTIFS('Invoice Ledger'!B:B,A29,'Invoice Ledger'!I:I,">0")
A30: PENTA | B30: =SUMIFS('Invoice Ledger'!I:I,'Invoice Ledger'!B:B,A30) | C30: =COUNTIFS('Invoice Ledger'!B:B,A30,'Invoice Ledger'!I:I,">0")
A31: Pence | B31: =SUMIFS('Invoice Ledger'!I:I,'Invoice Ledger'!B:B,A31) | C31: =COUNTIFS('Invoice Ledger'!B:B,A31,'Invoice Ledger'!I:I,">0")
... A34: VMG | B34: =SUMIFS('Invoice Ledger'!I:I,'Invoice Ledger'!B:B,A34) | C34: =COUNTIFS('Invoice Ledger'!B:B,A34,'Invoice Ledger'!I:I,">0")

Sheet QBO Tie-out
A1: Item | B1: Amount | C1: Source | D1: Read
A2: Hub annual billings YTD (fee less discount) | B2: ='Revenue YTD'!B15 | C2: Hub 2026 Rev Report, as of 2026-10-15 | D2: Matches Hub total $982,428 only if every row is included
A3: QuickBooks Sales by Customer YTD (accrual) | B3: 59100 | C3: QBO, 2026-01-01 to 2026-10-15 | D3: One customer (PB South), June only
A4: QuickBooks Sales by Customer YTD (cash) | B4: 59100 | C4: QBO, same period | D4: Identical to accrual: the connector report does not distinguish
A5: QuickBooks open A/R at 2026-10-15 | B5: 0 | C5: QBO A/R aging | D5: No open receivables recorded
A6: QuickBooks invoices, last 180 days | B6: 0 | C6: QBO invoice list | D6: No invoices recorded
A7: QuickBooks September 2026 total income | B7: 117500 | C7: QBO P&L Sep | D7: Not tied to a customer (known issue #2)
A8: Gap: Hub billings less QBO customer-tied sales | B8: =B2-B3 | C8: Computed | D8: Revenue is not being booked as customer invoices in QBO; Joel to confirm how it is booked

Sheet BvA Sep
A1: EPG September 2026: Budget vs Actual. BOOKS NOT CLOSED. Basis unconfirmed. Budget lines PROPOSED, not approved.
A2: Favourable = income above budget, expense below budget. Over 10% is flagged.
A4: Line | B4: Budget (proposed) | C4: Actual (QuickBooks, basis unconfirmed) | D4: Variance $ | E4: Variance % | F4: Flag | G4: Note
A5: Sales (income) | C5: 117500 | D5: =IF(B5="","",C5-B5) | E5: =IF(OR(B5="",B5=0),"",D5/B5) | F5: =IF(B5="","No budget yet",IF(ABS(E5)<=0.1,"Within 10%",IF(D5>0,"Favourable","Unfavourable"))) | G5: Income not tied to a customer in QBO
A6: Contract labor | C6: 8000 | D6: =IF(B6="","",C6-B6) | E6: =IF(OR(B6="",B6=0),"",D6/B6) | F6: =IF(B6="","No budget yet",IF(ABS(E6)<=0.1,"Within 10%",IF(D6<0,"Favourable","Unfavourable")))
A7: Insurance | C7: 4232.44 | D7: =IF(B7="","",C7-B7) | E7: =IF(OR(B7="",B7=0),"",D7/B7) | F7: =IF(B7="","No budget yet",IF(ABS(E7)<=0.1,"Within 10%",IF(D7<0,"Favourable","Unfavourable")))
A8: Payroll expenses | C8: 2225.19 | D8: =IF(B8="","",C8-B8) | E8: =IF(OR(B8="",B8=0),"",D8/B8) | F8: =IF(B8="","No budget yet",IF(ABS(E8)<=0.1,"Within 10%",IF(D8<0,"Favourable","Unfavourable"))) | G8: Payroll per QBO; Gusto totals not reconciled
A9: Rent | C9: 1004.95 | D9: =IF(B9="","",C9-B9) | E9: =IF(OR(B9="",B9=0),"",D9/B9) | F9: =IF(B9="","No budget yet",IF(ABS(E9)<=0.1,"Within 10%",IF(D9<0,"Favourable","Unfavourable")))
A10: Memberships & subscriptions | C10: 1150 | D10: =IF(B10="","",C10-B10) | E10: =IF(OR(B10="",B10=0),"",D10/B10) | F10: =IF(B10="","No budget yet",IF(ABS(E10)<=0.1,"Within 10%",IF(D10<0,"Favourable","Unfavourable")))
A11: Office expenses | C11: 440.38 | D11: =IF(B11="","",C11-B11) | E11: =IF(OR(B11="",B11=0),"",D11/B11) | F11: =IF(B11="","No budget yet",IF(ABS(E11)<=0.1,"Within 10%",IF(D11<0,"Favourable","Unfavourable")))
A12: Team building | C12: 387.76 | D12: =IF(B12="","",C12-B12) | E12: =IF(OR(B12="",B12=0),"",D12/B12) | F12: =IF(B12="","No budget yet",IF(ABS(E12)<=0.1,"Within 10%",IF(D12<0,"Favourable","Unfavourable")))
A13: Business loan interest | C13: 250 | D13: =IF(B13="","",C13-B13) | E13: =IF(OR(B13="",B13=0),"",D13/B13) | F13: =IF(B13="","No budget yet",IF(ABS(E13)<=0.1,"Within 10%",IF(D13<0,"Favourable","Unfavourable")))
A14: Utilities | C14: 88.6 | D14: =IF(B14="","",C14-B14) | E14: =IF(OR(B14="",B14=0),"",D14/B14) | F14: =IF(B14="","No budget yet",IF(ABS(E14)<=0.1,"Within 10%",IF(D14<0,"Favourable","Unfavourable")))
A15: Meals and travel | C15: 17.64 | D15: =IF(B15="","",C15-B15) | E15: =IF(OR(B15="",B15=0),"",D15/B15) | F15: =IF(B15="","No budget yet",IF(ABS(E15)<=0.1,"Within 10%",IF(D15<0,"Favourable","Unfavourable")))
A16: Professional development (other expense) | C16: 1150 | D16: =IF(B16="","",C16-B16) | E16: =IF(OR(B16="",B16=0),"",D16/B16) | F16: =IF(B16="","No budget yet",IF(ABS(E16)<=0.1,"Within 10%",IF(D16<0,"Favourable","Unfavourable")))
A17: Total expenses incl. other expense | C17: =SUM(C6:C16)
A18: Net income | C18: =C5-C17
A19: Check vs QuickBooks: operating expenses $17,796.96 + other expense $1,150.00 = $18,946.96; net income $98,553.04. Lines above tie to the summary.
A21: Proposed monthly revenue budget (2026 ramp, from the Hub Annual Ramp Goal tab) | B21: Rev goal | C21: Hub billed by start month | D21: Variance $
A22: Jan to May shown from the Hub tab; Jun to Dec to be filled when Kev and Chris confirm the ramp ($2,350,000 annual). PROPOSED.
A23: 2026-01 | B23: 114286 | C23: ='Revenue YTD'!B2 | D23: =C23-B23
A24: 2026-02 | B24: 128571 | C24: ='Revenue YTD'!B3 | D24: =C24-B24
A25: 2026-03 | B25: 142857 | C25: ='Revenue YTD'!B4 | D25: =C25-B25
A26: 2026-04 | B26: 157143 | C26: ='Revenue YTD'!B5 | D26: =C26-B26
A27: 2026-05 | B27: 171429 | C27: ='Revenue YTD'!B6 | D27: =C27-B27

Sheet Questions
A1: For | B1: Question
A2: Joel | B2: How were 2026 sales booked in QuickBooks, since there are no invoices and no open A/R? Sales receipts, journal entries or deposits straight to Sales?
A3: Joel | B3: Is the QuickBooks P&L on accrual or cash? Please run the accrual P&L for September and share the export.
A4: Joel | B4: What ties the $117,500 of September income to customers?
A5: Joel | B5: Send Chase deposits by month so the Paid column can be matched to each invoice.
A6: Radar | B6: Invoice 62502 and 62053 (both $40,000, same client, role and start): two placements or one counted twice?
A7: Radar | B7: Invoice 62026-A and 62026-B (two $15,000 lines, net 30 and net 90): split bill or double count?
A8: Radar | B8: Jan to Feb outbox invoices (62021 to 62033) not found by subject; where were they sent from?
A9: Kev | B9: Confirm the monthly revenue budget ramp and whether revenue should be recognised at start date (assumed here).
A10: Radar | B10: Hub Annual Ramp Goal tab shows Q1 actual $403,903, but Rev Report rows by start month give $305,570 for Jan to Mar. Which is right?
A11: Kev | B11: Add "Invoice sent" and "Paid" columns to the Hub Rev Report so payments can be matched automatically.
